
C:\Windows\system32>C:\Python27\ArcGISx6410.6\python.exe C:\Sourcecode\Other\VaccineChecker\VaccinneChecker.py 
2021-02-21
False
Emailing results table to: eri*@gmail.com
Traceback (most recent call last):
  File "C:\Sourcecode\Other\VaccineChecker\VaccinneChecker.py", line 45, in <module>
    SendEmail()
  File "C:\Sourcecode\Other\VaccineChecker\VaccinneChecker.py", line 37, in SendEmail
    subject="Louisville Walgreens are taking COVID appointments"
  File "C:\Python27\ArcGISx6410.6\lib\site-packages\yagmail\sender.py", line 153, in send
    self.login()
  File "C:\Python27\ArcGISx6410.6\lib\site-packages\yagmail\sender.py", line 206, in login
    self._login(self.credentials)
  File "C:\Python27\ArcGISx6410.6\lib\site-packages\yagmail\sender.py", line 225, in _login
    self.smtp.login(self.user, password)
  File "C:\Python27\ArcGISx6410.6\lib\smtplib.py", line 623, in login
    raise SMTPAuthenticationError(code, resp)
smtplib.SMTPAuthenticationError: (535, '5.7.8 Username and Password not accepted. Learn more at\n5.7.8  https://support.google.com/mail/?p=BadCredentials k12sm822090qtu.48 - gsmtp')
